
<?xml version="1.0" encoding="utf-8"?>
<!-- =================================================================================== -->
<!-- |    This document was autogenerated by xacro from spot.urdf.xacro                | -->
<!-- |    IT WAS EDITED BY HAND, yeah I know...                                        | -->
<!-- =================================================================================== -->
<robot name="spot">
  <material name="maroon">
    <color rgba="0.5 0.2 0.2 1"/>
  </material>
  <material name="lblue">
    <color rgba="0.01 0.01 0.5 1"/>
  </material>
  <material name="orange">
    <color rgba="1.0 0.5 0.0 1"/>
  </material>
  <material name="black">
    <color rgba="0.1 0.1 0.1 1"/>
  </material>
  <material name="gray">
    <color rgba="0.6 0.6 0.6 1"/>
  </material>
  <material name="white">
    <color rgba="1.0 1.0 1.0 1"/>
  </material>
  <material name="yellow">
    <color rgba="1.0 1.0 0.0 1"/>
  </material>
  <material name="cgray">
    <color rgba="0.6 0.6 0.6 0.5"/>
  </material>
  <material name="blue">
    <color rgba="0.2 0.2 0.8 1"/>
  </material>
  <material name="green">
    <color rgba="0.2 0.8 0.2 1"/>
  </material>
  <!-- Left Leg: prefix  Left Leg: prefix is front or rear -->
  <!--   <xacro:macro name="LeftLeg" params="prefix reflect">
    <link name="${prefix}_Left_Leg">
        <visual>
            <geometry>
                <box size="${leglen} 0.1 0.2"/>
            </geometry>
            <origin xyz="0 0 -${leglen/2}" rpy="0 ${pi/2} 0"/>
            <material name="white"/>
        </visual>
        <collision>
            <geometry>
                <box size="${leglen} 0.1 0.2"/>
            </geometry>
            <origin xyz="0 0 -${leglen/2}" rpy="0 ${pi/2} 0"/>
        </collision>
        <xacro:default_inertial mass="10"/>
    </link>
    <joint name="base_to_${prefix}_leg" type="fixed">
        <parent link="base_link"/>
        <child link="${prefix}_leg"/>
        <origin xyz="0 ${reflect*(width+.02)} 0.25" />
    </joint>
</xacro:macro> -->
  <!-- Robot description -->
  <!-- STATIC Links -->
  <link name="base_link">
    <visual>
      <origin rpy="0 0 1.57079632679" xyz="-0.16 0.035 -0.045"/>
      <geometry>
        <mesh filename="package://mini_ros/stl/OpenQuadruped/MAINBODY.stl" scale="1 1 1"/>
      </geometry>
      <material name="maroon"/>
    </visual>
    <collision>
      <origin rpy="0 0 1.57079632679" xyz="0 0 0"/>
      <geometry>
        <box size="0.05 0.2 0.08"/>
      </geometry>
    </collision>
    <inertial>
      <mass value="0.6"/>
      <origin rpy="0 0 0" xyz="0 0 0"/>
      <!-- Inertial Axes -->
      <inertia ixx="0.00232" ixy="0" ixz="0" iyx="0" iyy="0.000445" iyz="0" izx="0" izy="0" izz="0.002125"/>
    </inertial>
  </link>
  <!-- m to mm -->
  <link name="battery">
    <visual>
      <origin rpy="0 0 1.57079632679" xyz="-0.15 0.035 -0.022"/>
      <geometry>
        <mesh filename="package://mini_ros/stl/OpenQuadruped/Battery.stl" scale="1 1 1"/>
      </geometry>
      <material name="lblue"/>
    </visual>
    <inertial>
      <mass value="1"/>
      <origin rpy="0 0 0" xyz="0 0 0"/>
      <!-- Inertial Axes -->
      <inertia ixx="0.000723366666667" ixy="0" ixz="0" iyx="0" iyy="9.93333333333e-05" iyz="0" izx="0" izy="0" izz="0.000777633333333"/>
    </inertial>
  </link>
  <gazebo reference="battery">
  </gazebo>
  <!-- m to mm -->
  <link name="cfr_core">
    <visual>
      <origin rpy="0 0 1.57079632679" xyz="-0.15 0.035 -0.022"/>
      <geometry>
        <mesh filename="package://mini_ros/stl/OpenQuadruped/cfr_core.stl" scale="1 1 1"/>
      </geometry>
      <material name="black"/>
    </visual>
    <inertial>
      <mass value="0.05"/>
      <origin rpy="0 0 0" xyz="0 0 0"/>
      <!-- Inertial Axes -->
      <inertia ixx="9.04208333333e-05" ixy="0" ixz="0" iyx="0" iyy="1.24166666667e-05" iyz="0" izx="0" izy="0" izz="9.72041666667e-05"/>
    </inertial>
  </link>
  <gazebo reference="cfr_core">
    <material>Gazebo/Black</material>
  </gazebo>
<!-- m to mm -->
  <link name="m5paper">
    <visual>
      <origin rpy="0 0 1.57079632679" xyz="-0.15 0.035 -0.022"/>
      <geometry>
        <mesh filename="package://mini_ros/stl/OpenQuadruped/m5paper.stl" scale="1 1 1"/>
      </geometry>
      <material name="gray"/>
    </visual>
    <inertial>
      <mass value="0.05"/>
      <origin rpy="0 0 0" xyz="0 0 0"/>
      <!-- Inertial Axes -->
      <inertia ixx="9.04208333333e-05" ixy="0" ixz="0" iyx="0" iyy="1.24166666667e-05" iyz="0" izx="0" izy="0" izz="9.72041666667e-05"/>
    </inertial>
  </link>
  <gazebo reference="m5paper">
  </gazebo>
  <!-- m to mm -->
  <link name="rpi_lidar">
    <visual>
      <origin rpy="0 0 1.57079632679" xyz="-0.15 0.035 -0.022"/>
      <geometry>
        <mesh filename="package://mini_ros/stl/OpenQuadruped/lidar.stl" scale="1 1 1"/>
      </geometry>
      <material name="black"/>
    </visual>
    <collision>
      <origin rpy="0 0 1.57079632679" xyz="0.125 0 0.1"/>
      <geometry>
        <box size="0.08 0.08 0.05"/>
      </geometry>
    </collision>
    <inertial>
      <mass value="0.25"/>
      <origin rpy="0 0 0" xyz="0 0 0"/>
      <!-- Inertial Axes -->
      <inertia ixx="3.70833333333e-05" ixy="0" ixz="0" iyx="0" iyy="3.70833333333e-05" iyz="0" izx="0" izy="0" izz="5.33333333333e-05"/>
    </inertial>
  </link>
  <gazebo reference="rpi_lidar">
    <material>Gazebo/Black</material>
  </gazebo>
  <!-- m to mm -->
  <link name="rpi_5">
    <visual>
      <origin rpy="0 0 1.57079632679" xyz="-0.15 0.035 -0.022"/>
      <geometry>
        <mesh filename="package://mini_ros/stl/OpenQuadruped/RPI5.stl" scale="1 1 1"/>
      </geometry>
      <material name="green"/>
    </visual>
    <inertial>
      <mass value="0.1"/>
      <origin rpy="0 0 0" xyz="0 0 0"/>
      <!-- Inertial Axes -->
      <inertia ixx="9.04208333333e-05" ixy="0" ixz="0" iyx="0" iyy="1.24166666667e-05" iyz="0" izx="0" izy="0" izz="9.72041666667e-05"/>
    </inertial>
  </link>
  <gazebo reference="rpi_5">
  </gazebo>
  <!-- m to mm -->
  <link name="oak_d_lite">
    <visual>
      <origin rpy="0 0 1.57079632679" xyz="-0.15 0.035 -0.022"/>
      <geometry>
        <mesh filename="package://mini_ros/stl/OpenQuadruped/OAKD_LITE.stl" scale="1 1 1"/>
      </geometry>
      <material name="black"/>
    </visual>
    <inertial>
      <mass value="0.1"/>
      <origin rpy="0 0 0" xyz="0 0 0"/>
      <!-- Inertial Axes -->
      <inertia ixx="9.04208333333e-05" ixy="0" ixz="0" iyx="0" iyy="1.24166666667e-05" iyz="0" izx="0" izy="0" izz="9.72041666667e-05"/>
    </inertial>
  </link>
  <gazebo reference="oak_d_lite">
    <material>Gazebo/Black</material>
  </gazebo>
  <!-- m to mm -->
  <link name="insta_360">
    <visual>
      <origin rpy="0 0 1.57079632679" xyz="-0.15 0.035 -0.022"/>
      <geometry>
        <mesh filename="package://mini_ros/stl/OpenQuadruped/INSTA360.stl" scale="1 1 1"/>
      </geometry>
      <material name="black"/>
    </visual>
    <collision>
      <origin rpy="0 0 1.57079632679" xyz="-0.1 0 0.135"/>
      <geometry>
        <box size="0.03 0.05 0.1"/>
      </geometry>
    </collision>
    <inertial>
      <mass value="0.5"/>
      <origin rpy="0 0 0" xyz="0 0 0"/>
      <!-- Inertial Axes -->
      <inertia ixx="5.20833333333e-05" ixy="0" ixz="0" iyx="0" iyy="4.54166666667e-05" iyz="0" izx="0" izy="0" izz="1.41666666667e-05"/>
    </inertial>
  </link>
  <gazebo reference="insta_360">
    <material>Gazebo/Black</material>
  </gazebo>
  <!-- m to mm -->
  <link name="front">
    <visual>
      <origin rpy="0 0 1.57079632679" xyz="-0.16 0.035 -0.045"/>
      <geometry>
        <mesh filename="package://mini_ros/stl/OpenQuadruped/Front.stl" scale="1 1 1"/>
      </geometry>
      <material name="maroon"/>
    </visual>
    <collision>
      <origin rpy="0 0 1.57079632679" xyz="0.16 0 0.006"/>
      <geometry>
        <box size="0.114 0.045 0.085"/>
      </geometry>
    </collision>
    <inertial>
      <mass value="0.1"/>
      <origin rpy="0 0 0" xyz="0 0 0"/>
      <!-- Inertial Axes -->
      <inertia ixx="7.70833333333e-05" ixy="0" ixz="0" iyx="0" iyy="0.000168508333333" iyz="0" izx="0" izy="0" izz="0.000125175"/>
    </inertial>
  </link>
  <gazebo reference="front">
  </gazebo>
  <!-- m to mm -->
  <link name="back">
    <visual>
      <origin rpy="0 0 1.57079632679" xyz="-0.16 0.035 -0.045"/>
      <geometry>
        <mesh filename="package://mini_ros/stl/OpenQuadruped/m5fire_black.stl" scale="1 1 1"/>
      </geometry>
      <material name="black"/>
    </visual>
    <collision>
      <origin rpy="0 0 1.57079632679" xyz="-0.15 0 0.006"/>
      <geometry>
        <box size="0.06 0.005 0.06"/>
      </geometry>
    </collision>
    <inertial>
      <mass value="0.3"/>
      <origin rpy="0 0 0" xyz="0 0 0"/>
      <!-- Inertial Axes -->
      <inertia ixx="3.02083333333e-05" ixy="0" ixz="0" iyx="0" iyy="6e-05" iyz="0" izx="0" izy="0" izz="3.02083333333e-05"/>
    </inertial>
  </link>
  <gazebo reference="back">
    <material>Gazebo/Black</material>
  </gazebo>
  <!-- m to mm -->
  <link name="front_bracket">
    <visual>
      <origin rpy="0 0 1.57079632679" xyz="-0.16 0.035 -0.045"/>
      <geometry>
        <mesh filename="package://mini_ros/stl/OpenQuadruped/Front_Bracket.stl" scale="1 1 1"/>
      </geometry>
      <material name="maroon"/>
    </visual>
    <collision>
      <origin rpy="0 0 1.57079632679" xyz="0.1 0 0"/>
      <geometry>
        <box size="0.025 0.075 0.085"/>
      </geometry>
    </collision>
    <inertial>
      <mass value="0.1"/>
      <origin rpy="0 0 0" xyz="0 0 0"/>
      <!-- Inertial Axes -->
      <inertia ixx="0.000107083333333" ixy="0" ixz="0" iyx="0" iyy="6.54166666667e-05" iyz="0" izx="0" izy="0" izz="5.20833333333e-05"/>
    </inertial>
  </link>
  <gazebo reference="front_bracket">
  </gazebo>
  <!-- m to mm -->
  <link name="back_bracket">
    <visual>
      <origin rpy="0 0 1.57079632679" xyz="-0.16 0.035 -0.045"/>
      <geometry>
        <mesh filename="package://mini_ros/stl/OpenQuadruped/Back_Bracket.stl" scale="1 1 1"/>
      </geometry>
      <material name="maroon"/>
    </visual>
    <collision>
      <origin rpy="0 0 1.57079632679" xyz="-0.1 0 0"/>
      <geometry>
        <box size="0.1 0.075 0.085"/>
      </geometry>
    </collision>
    <inertial>
      <mass value="0.1"/>
      <origin rpy="0 0 0" xyz="0 0 0"/>
      <!-- Inertial Axes -->
      <inertia ixx="0.000107083333333" ixy="0" ixz="0" iyx="0" iyy="0.000143541666667" iyz="0" izx="0" izy="0" izz="0.000130208333333"/>
    </inertial>
  </link>
  <gazebo reference="back_bracket">
  </gazebo>
<!-- m to mm -->
  <link name="front_left_hip">
    <visual>
      <origin rpy="0 0 1.57079632679" xyz="-0.258 -0.0044 -0.062"/>
      <geometry>
        <mesh filename="package://mini_ros/stl/OpenQuadruped/LEFT_HIP.stl" scale="1 1 1"/>
      </geometry>
      <material name="white"/>
    </visual>
    <collision>
      <origin rpy="0 0 1.57079632679" xyz="0.015 0.005 -0.01"/>
      <geometry>
        <box size="0.05 0.065 0.065"/>
      </geometry>
    </collision>
    <inertial>
      <mass value="0.2"/>
      <origin rpy="0 0 0" xyz="0 0.075 0"/>
      <!-- Inertial Axes -->
      <inertia ixx="0.000140833333333" ixy="0" ixz="0" iyx="0" iyy="0.000112083333333" iyz="0" izx="0" izy="0" izz="0.000112083333333"/>
    </inertial>
  </link>
  <gazebo reference="front_left_hip">
  </gazebo>
  <joint name="motor_front_left_hip" type="revolute">
    <axis xyz="1 0 0"/>
    <origin rpy="0 0 0" xyz="0.0995 0.0394 0.017"/>
    <parent link="front_bracket"/>
    <child link="front_left_hip"/>
    <limit effort="4.0" lower="-1.04" upper="1.04" velocity="4.0"/>
    <joint_properties damping="0.0" friction="0.0"/>
  </joint>
  <link name="front_left_upper_leg">
    <visual>
      <origin rpy="0 0 1.57079632679" xyz="-0.252 -0.06 -0.053"/>
      <geometry>
        <mesh filename="package://mini_ros/stl/OpenQuadruped/LEFT_UPPER_LEG.stl" scale="1 1 1"/>
      </geometry>
      <material name="maroon"/>
    </visual>
    <collision>
      <origin rpy="0 0 1.57079632679" xyz="0 0.01 -0.05"/>
      <geometry>
        <box size="0.035 0.035 0.11"/>
      </geometry>
    </collision>
    <inertial>
      <mass value="0.13"/>
      <origin rpy="0 0 0" xyz="-0.005 0.0175 -0.055"/>
      <!-- Inertial Axes -->
      <inertia ixx="0.000144354166667" ixy="0" ixz="0" iyx="0" iyy="0.000144354166667" iyz="0" izx="0" izy="0" izz="2.65416666667e-05"/>
    </inertial>
  </link>
  <gazebo reference="front_left_upper_leg">
  </gazebo>
  <joint name="motor_front_left_upper_leg" type="revolute">
    <axis xyz="0 1 0"/>
    <origin rpy="0 0 0" xyz="0.0015 0.045 -0.011"/>
    <parent link="front_left_hip"/>
    <child link="front_left_upper_leg"/>
    <limit effort="4.0" lower="-1.57079632679" upper="2.59" velocity="4.0"/>
    <joint_properties damping="0.0" friction="0.0"/>
  </joint>
  <link name="front_left_upper_servo">
    <visual>
      <origin rpy="0 0 1.57079632679" xyz="-0.252 -0.06 -0.053"/>
      <geometry>
        <mesh filename="package://mini_ros/stl/OpenQuadruped/LEFT_UPPER_SERVO.stl" scale="1 1 1"/>
      </geometry>
      <material name="black"/>
    </visual>
    <inertial>
      <mass value="0.005"/>
      <origin rpy="0 0 0" xyz="-0.005 -0.0175 -0.053"/>
      <!-- Inertial Axes -->
      <inertia ixx="3.52083333333e-06" ixy="0" ixz="0" iyx="0" iyy="2.80208333333e-06" iyz="0" izx="0" izy="0" izz="2.80208333333e-06"/>
    </inertial>
  </link>
  <gazebo reference="front_left_upper_servo">
    <material>Gazebo/Black</material>
  </gazebo>
  <joint name="front_left_leg_upper_servo" type="fixed">
    <origin rpy="0 0 0" xyz="0 0 0"/>
    <parent link="front_left_upper_leg"/>
    <child link="front_left_upper_servo"/>
  </joint>
  <link name="front_left_upper_CFP">
    <visual>
      <origin rpy="0 0 1.57079632679" xyz="-0.252 -0.06 -0.055"/>
      <geometry>
        <mesh filename="package://mini_ros/stl/OpenQuadruped/LEFT_UPPER_CFP.stl" scale="1 1 1"/>
      </geometry>
      <material name="black"/>
    </visual>
    <inertial>
      <mass value="0.005"/>
      <origin rpy="0 0 0" xyz="-0.005 -0.0175 -0.053"/>
      <!-- Inertial Axes -->
      <inertia ixx="3.52083333333e-06" ixy="0" ixz="0" iyx="0" iyy="2.80208333333e-06" iyz="0" izx="0" izy="0" izz="2.80208333333e-06"/>
    </inertial>
  </link>
  <gazebo reference="front_left_upper_CFP">
    <material>Gazebo/Black</material>
  </gazebo>
  <joint name="front_left_leg_upper_CFP" type="fixed">
    <origin rpy="0 0 0" xyz="0 0 0"/>
    <parent link="front_left_upper_leg"/>
    <child link="front_left_upper_CFP"/>
  </joint>
  <link name="front_left_lower_leg">
    <visual>
      <origin rpy="0 0 1.57079632679" xyz="-0.247 -0.068 0.0535"/>
      <geometry>
        <mesh filename="package://mini_ros/stl/OpenQuadruped/LEFT_LOWER_LEG.stl" scale="1 1 1"/>
      </geometry>
      <material name="yellow"/>
    </visual>
    <collision>
      <origin rpy="0 0 1.57079632679" xyz="0 0.01 -0.04"/>
      <geometry>
        <box size="0.035 0.035 0.11"/>
      </geometry>
    </collision>
    <inertial>
      <mass value="0.05"/>
      <origin rpy="0 0 0" xyz="-0.01 0 -0.06"/>
      <!-- Inertial Axes -->
      <inertia ixx="5.55208333333e-05" ixy="0" ixz="0" iyx="0" iyy="5.55208333333e-05" iyz="0" izx="0" izy="0" izz="1.02083333333e-05"/>
    </inertial>
  </link>
  <gazebo reference="front_left_lower_leg">
  </gazebo>
  <joint name="motor_front_left_lower_leg" type="revolute">
    <axis xyz="0 1 0"/>
    <origin rpy="0 0 0" xyz="-0.005 0.002 -0.1068"/>
    <parent link="front_left_upper_leg"/>
    <child link="front_left_lower_leg"/>
    <limit effort="4.0" lower="-2.9" upper="1.57079632679" velocity="4.0"/>
    <joint_properties damping="0.0" friction="0.0"/>
  </joint>
  <link name="front_left_lower_servo">
    <visual>
      <origin rpy="0 0 1.57079632679" xyz="-0.247 -0.068 0.0535"/>
      <geometry>
        <mesh filename="package://mini_ros/stl/OpenQuadruped/LEFT_LOWER_SERVO.stl" scale="1 1 1"/>
      </geometry>
      <material name="black"/>
    </visual>
    <inertial>
      <mass value="0.005"/>
      <origin rpy="0 0 0" xyz="-0.005 -0.0175 -0.053"/>
      <!-- Inertial Axes -->
      <inertia ixx="3.52083333333e-06" ixy="0" ixz="0" iyx="0" iyy="2.80208333333e-06" iyz="0" izx="0" izy="0" izz="2.80208333333e-06"/>
    </inertial>
  </link>
  <gazebo reference="front_left_lower_servo">
    <material>Gazebo/Black</material>
  </gazebo>
  <joint name="front_left_leg_lower_servo" type="fixed">
    <origin rpy="0 0 0" xyz="0 0 0"/>
    <parent link="front_left_lower_leg"/>
    <child link="front_left_lower_servo"/>
  </joint>
  <link name="front_left_lower_CFP">
    <visual>
      <origin rpy="0 0 1.57079632679" xyz="-0.247 -0.068 0.0535"/>
      <geometry>
        <mesh filename="package://mini_ros/stl/OpenQuadruped/LEFT_LOWER_CFP.stl" scale="1 1 1"/>
      </geometry>
      <material name="black"/>
    </visual>
    <inertial>
      <mass value="0.005"/>
      <origin rpy="0 0 0" xyz="-0.005 -0.0175 -0.053"/>
      <!-- Inertial Axes -->
      <inertia ixx="3.52083333333e-06" ixy="0" ixz="0" iyx="0" iyy="2.80208333333e-06" iyz="0" izx="0" izy="0" izz="2.80208333333e-06"/>
    </inertial>
  </link>
  <gazebo reference="front_left_lower_CFP">
    <material>Gazebo/Black</material>
  </gazebo>
  <joint name="front_left_leg_lower_CFP" type="fixed">
    <origin rpy="0 0 0" xyz="0 0 0"/>
    <parent link="front_left_lower_leg"/>
    <child link="front_left_lower_CFP"/>
  </joint>
  <link name="front_left_lower_IMU">
    <visual>
      <origin rpy="0 0 1.57079632679" xyz="-0.247 -0.068 0.0535"/>
      <geometry>
        <mesh filename="package://mini_ros/stl/OpenQuadruped/LEFT_FOOT_IMU.stl" scale="1 1 1"/>
      </geometry>
      <material name="blue"/>
    </visual>
    <inertial>
      <mass value="0.005"/>
      <origin rpy="0 0 0" xyz="-0.005 -0.0175 -0.053"/>
      <!-- Inertial Axes -->
      <inertia ixx="3.52083333333e-06" ixy="0" ixz="0" iyx="0" iyy="2.80208333333e-06" iyz="0" izx="0" izy="0" izz="2.80208333333e-06"/>
    </inertial>
  </link>
  <gazebo reference="front_left_lower_IMU">
  </gazebo>
  <joint name="front_left_leg_lower_IMU" type="fixed">
    <origin rpy="0 0 0" xyz="0 0 0"/>
    <parent link="front_left_lower_leg"/>
    <child link="front_left_lower_IMU"/>
  </joint>
  <link name="front_left_foot">
    <visual>
      <origin rpy="0 0 1.57079632679" xyz="-0.247 -0.068 0.18"/>
      <geometry>
        <mesh filename="package://mini_ros/stl/OpenQuadruped/LEFT_FOOT.stl" scale="1 1 1"/>
      </geometry>
      <material name="orange"/>
    </visual>
    <collision>
      <origin rpy="0 0 1.57079632679" xyz="-0.247 -0.068 0.18"/>
      <geometry>
        <mesh filename="package://mini_ros/stl/OpenQuadruped/LEFT_FOOT.stl" scale="1 1 1"/>
      </geometry>
      <contact_coefficients mu="10.1"/>
    </collision>
    <inertial>
      <mass value="0.005"/>
      <origin rpy="0 0 0" xyz="0 0 0"/>
      <!-- Inertial Axes -->
      <inertia ixx="3.52083333333e-06" ixy="0" ixz="0" iyx="0" iyy="2.80208333333e-06" iyz="0" izx="0" izy="0" izz="2.80208333333e-06"/>
    </inertial>
  </link>
  <gazebo reference="front_left_foot">
    <kp>1000000.0</kp>
    <kd>1.0</kd>
    <mu1>0.8</mu1>
    <mu2>0.8</mu2>
    <maxVel>0.0</maxVel>
    <minDepth>0.001</minDepth>
    <material>Gazebo/Red</material>
  </gazebo>
  <joint name="front_left_leg_foot" type="fixed">
    <origin rpy="0 0 0" xyz="0 0 -0.1265"/>
    <parent link="front_left_lower_leg"/>
    <child link="front_left_foot"/>
  </joint>

  <link name="back_left_hip">
    <visual>
      <origin rpy="0 0 1.57079632679" xyz="-0.258 -0.0044 -0.062"/>
      <geometry>
        <mesh filename="package://mini_ros/stl/OpenQuadruped/LEFT_HIP.stl" scale="1 1 1"/>
      </geometry>
      <material name="white"/>
    </visual>
    <collision>
      <origin rpy="0 0 1.57079632679" xyz="0.015 0.005 -0.01"/>
      <geometry>
        <box size="0.05 0.065 0.065"/>
      </geometry>
    </collision>
    <inertial>
      <mass value="0.2"/>
      <origin rpy="0 0 0" xyz="0 0.075 0"/>
      <!-- Inertial Axes -->
      <inertia ixx="0.000140833333333" ixy="0" ixz="0" iyx="0" iyy="0.000112083333333" iyz="0" izx="0" izy="0" izz="0.000112083333333"/>
    </inertial>
  </link>
  <gazebo reference="back_left_hip">
  </gazebo>
  <joint name="motor_back_left_hip" type="revolute">
    <axis xyz="1 0 0"/>
    <origin rpy="0 0 0" xyz="-0.1075 0.0394 0.017"/>
    <parent link="back_bracket"/>
    <child link="back_left_hip"/>
    <limit effort="4.0" lower="-1.04" upper="1.04" velocity="4.0"/>
    <joint_properties damping="0.0" friction="0.0"/>
  </joint>
  <link name="back_left_upper_leg">
    <visual>
      <origin rpy="0 0 1.57079632679" xyz="-0.252 -0.06 -0.053"/>
      <geometry>
        <mesh filename="package://mini_ros/stl/OpenQuadruped/LEFT_UPPER_LEG.stl" scale="1 1 1"/>
      </geometry>
      <material name="maroon"/>
    </visual>
    <collision>
      <origin rpy="0 0 1.57079632679" xyz="0 0.01 -0.05"/>
      <geometry>
        <box size="0.035 0.035 0.11"/>
      </geometry>
    </collision>
    <inertial>
      <mass value="0.13"/>
      <origin rpy="0 0 0" xyz="-0.005 0.0175 -0.055"/>
      <!-- Inertial Axes -->
      <inertia ixx="0.000144354166667" ixy="0" ixz="0" iyx="0" iyy="0.000144354166667" iyz="0" izx="0" izy="0" izz="2.65416666667e-05"/>
    </inertial>
  </link>
  <gazebo reference="back_left_upper_leg">
  </gazebo>
  <joint name="motor_back_left_upper_leg" type="revolute">
    <axis xyz="0 1 0"/>
    <origin rpy="0 0 0" xyz="0.0015 0.045 -0.011"/>
    <parent link="back_left_hip"/>
    <child link="back_left_upper_leg"/>
    <limit effort="4.0" lower="-1.57079632679" upper="2.59" velocity="4.0"/>
    <joint_properties damping="0.0" friction="0.0"/>
  </joint>
  <link name="back_left_upper_servo">
    <visual>
      <origin rpy="0 0 1.57079632679" xyz="-0.252 -0.06 -0.053"/>
      <geometry>
        <mesh filename="package://mini_ros/stl/OpenQuadruped/LEFT_UPPER_SERVO.stl" scale="1 1 1"/>
      </geometry>
      <material name="black"/>
    </visual>
    <inertial>
      <mass value="0.005"/>
      <origin rpy="0 0 0" xyz="-0.005 -0.0175 -0.053"/>
      <!-- Inertial Axes -->
      <inertia ixx="3.52083333333e-06" ixy="0" ixz="0" iyx="0" iyy="2.80208333333e-06" iyz="0" izx="0" izy="0" izz="2.80208333333e-06"/>
    </inertial>
  </link>
  <gazebo reference="back_left_upper_servo">
    <material>Gazebo/Black</material>
  </gazebo>
  <joint name="back_left_leg_upper_servo" type="fixed">
    <origin rpy="0 0 0" xyz="0 0 0"/>
    <parent link="back_left_upper_leg"/>
    <child link="back_left_upper_servo"/>
  </joint>
  <link name="back_left_upper_CFP">
    <visual>
      <origin rpy="0 0 1.57079632679" xyz="-0.252 -0.06 -0.055"/>
      <geometry>
        <mesh filename="package://mini_ros/stl/OpenQuadruped/LEFT_UPPER_CFP.stl" scale="1 1 1"/>
      </geometry>
      <material name="black"/>
    </visual>
    <inertial>
      <mass value="0.005"/>
      <origin rpy="0 0 0" xyz="-0.005 -0.0175 -0.053"/>
      <!-- Inertial Axes -->
      <inertia ixx="3.52083333333e-06" ixy="0" ixz="0" iyx="0" iyy="2.80208333333e-06" iyz="0" izx="0" izy="0" izz="2.80208333333e-06"/>
    </inertial>
  </link>
  <gazebo reference="back_left_upper_CFP">
    <material>Gazebo/Black</material>
  </gazebo>
  <joint name="back_left_leg_upper_CFP" type="fixed">
    <origin rpy="0 0 0" xyz="0 0 0"/>
    <parent link="back_left_upper_leg"/>
    <child link="back_left_upper_CFP"/>
  </joint>
  <link name="back_left_lower_leg">
    <visual>
      <origin rpy="0 0 1.57079632679" xyz="-0.247 -0.068 0.0535"/>
      <geometry>
        <mesh filename="package://mini_ros/stl/OpenQuadruped/LEFT_LOWER_LEG.stl" scale="1 1 1"/>
      </geometry>
      <material name="yellow"/>
    </visual>
    <collision>
      <origin rpy="0 0 1.57079632679" xyz="0 0.01 -0.04"/>
      <geometry>
        <box size="0.035 0.035 0.11"/>
      </geometry>
    </collision>
    <inertial>
      <mass value="0.05"/>
      <origin rpy="0 0 0" xyz="-0.01 0 -0.06"/>
      <!-- Inertial Axes -->
      <inertia ixx="5.55208333333e-05" ixy="0" ixz="0" iyx="0" iyy="5.55208333333e-05" iyz="0" izx="0" izy="0" izz="1.02083333333e-05"/>
    </inertial>
  </link>
  <gazebo reference="back_left_lower_leg">
  </gazebo>
  <joint name="motor_back_left_lower_leg" type="revolute">
    <axis xyz="0 1 0"/>
    <origin rpy="0 0 0" xyz="-0.005 0.002 -0.1068"/>
    <parent link="back_left_upper_leg"/>
    <child link="back_left_lower_leg"/>
    <limit effort="4.0" lower="-2.9" upper="1.57079632679" velocity="4.0"/>
    <joint_properties damping="0.0" friction="0.0"/>
  </joint>
  <link name="back_left_lower_servo">
    <visual>
      <origin rpy="0 0 1.57079632679" xyz="-0.247 -0.068 0.0535"/>
      <geometry>
        <mesh filename="package://mini_ros/stl/OpenQuadruped/LEFT_LOWER_SERVO.stl" scale="1 1 1"/>
      </geometry>
      <material name="black"/>
    </visual>
    <inertial>
      <mass value="0.005"/>
      <origin rpy="0 0 0" xyz="-0.005 -0.0175 -0.053"/>
      <!-- Inertial Axes -->
      <inertia ixx="3.52083333333e-06" ixy="0" ixz="0" iyx="0" iyy="2.80208333333e-06" iyz="0" izx="0" izy="0" izz="2.80208333333e-06"/>
    </inertial>
  </link>
  <gazebo reference="back_left_lower_servo">
    <material>Gazebo/Black</material>
  </gazebo>
  <joint name="back_left_leg_lower_servo" type="fixed">
    <origin rpy="0 0 0" xyz="0 0 0"/>
    <parent link="back_left_lower_leg"/>
    <child link="back_left_lower_servo"/>
  </joint>
  <link name="back_left_lower_CFP">
    <visual>
      <origin rpy="0 0 1.57079632679" xyz="-0.247 -0.068 0.0535"/>
      <geometry>
        <mesh filename="package://mini_ros/stl/OpenQuadruped/LEFT_LOWER_CFP.stl" scale="1 1 1"/>
      </geometry>
      <material name="black"/>
    </visual>
    <inertial>
      <mass value="0.005"/>
      <origin rpy="0 0 0" xyz="-0.005 -0.0175 -0.053"/>
      <!-- Inertial Axes -->
      <inertia ixx="3.52083333333e-06" ixy="0" ixz="0" iyx="0" iyy="2.80208333333e-06" iyz="0" izx="0" izy="0" izz="2.80208333333e-06"/>
    </inertial>
  </link>
  <gazebo reference="back_left_lower_CFP">
    <material>Gazebo/Black</material>
  </gazebo>
  <joint name="back_left_leg_lower_CFP" type="fixed">
    <origin rpy="0 0 0" xyz="0 0 0"/>
    <parent link="back_left_lower_leg"/>
    <child link="back_left_lower_CFP"/>
  </joint>
  <link name="back_left_lower_IMU">
    <visual>
      <origin rpy="0 0 1.57079632679" xyz="-0.247 -0.068 0.0535"/>
      <geometry>
        <mesh filename="package://mini_ros/stl/OpenQuadruped/LEFT_FOOT_IMU.stl" scale="1 1 1"/>
      </geometry>
      <material name="blue"/>
    </visual>
    <inertial>
      <mass value="0.005"/>
      <origin rpy="0 0 0" xyz="-0.005 -0.0175 -0.053"/>
      <!-- Inertial Axes -->
      <inertia ixx="3.52083333333e-06" ixy="0" ixz="0" iyx="0" iyy="2.80208333333e-06" iyz="0" izx="0" izy="0" izz="2.80208333333e-06"/>
    </inertial>
  </link>
  <gazebo reference="back_left_lower_IMU">
  </gazebo>
  <joint name="back_left_leg_lower_IMU" type="fixed">
    <origin rpy="0 0 0" xyz="0 0 0"/>
    <parent link="back_left_lower_leg"/>
    <child link="back_left_lower_IMU"/>
  </joint>
  <link name="back_left_foot">
    <visual>
      <origin rpy="0 0 1.57079632679" xyz="-0.247 -0.068 0.18"/>
      <geometry>
        <mesh filename="package://mini_ros/stl/OpenQuadruped/LEFT_FOOT.stl" scale="1 1 1"/>
      </geometry>
      <material name="orange"/>
    </visual>
    <collision>
      <origin rpy="0 0 1.57079632679" xyz="-0.247 -0.068 0.18"/>
      <geometry>
        <mesh filename="package://mini_ros/stl/OpenQuadruped/LEFT_FOOT.stl" scale="1 1 1"/>
      </geometry>
      <contact_coefficients mu="10.1"/>
    </collision>
    <inertial>
      <mass value="0.005"/>
      <origin rpy="0 0 0" xyz="0 0 0"/>
      <!-- Inertial Axes -->
      <inertia ixx="3.52083333333e-06" ixy="0" ixz="0" iyx="0" iyy="2.80208333333e-06" iyz="0" izx="0" izy="0" izz="2.80208333333e-06"/>
    </inertial>
  </link>
  <gazebo reference="back_left_foot">
    <kp>1000000.0</kp>
    <kd>1.0</kd>
    <mu1>0.8</mu1>
    <mu2>0.8</mu2>
    <maxVel>0.0</maxVel>
    <minDepth>0.001</minDepth>
    <material>Gazebo/Red</material>
  </gazebo>
  <joint name="back_left_leg_foot" type="fixed">
    <origin rpy="0 0 0" xyz="0 0 -0.1265"/>
    <parent link="back_left_lower_leg"/>
    <child link="back_left_foot"/>
  </joint>





  





  <link name="front_right_hip">
    <visual>
      <origin rpy="0 0 1.57079632679" xyz="-0.258 0.074 -0.062"/>
      <geometry>
        <mesh filename="package://mini_ros/stl/OpenQuadruped/RIGHT_HIP.stl" scale="1 1 1"/>
      </geometry>
      <material name="white"/>
    </visual>
    <collision>
      <origin rpy="0 0 1.57079632679" xyz="0.015 -0.005 -0.01"/>
      <geometry>
        <box size="0.05 0.065 0.065"/>
      </geometry>
    </collision>
    <inertial>
      <mass value="0.2"/>
      <origin rpy="0 0 0" xyz="0 -0.075 0"/>
      <!-- Inertial Axes -->
      <inertia ixx="0.000140833333333" ixy="0" ixz="0" iyx="0" iyy="0.000112083333333" iyz="0" izx="0" izy="0" izz="0.000112083333333"/>
    </inertial>
  </link>
  <gazebo reference="front_right_hip">
  </gazebo>
  <joint name="motor_front_right_hip" type="revolute">
    <axis xyz="1 0 0"/>
    <origin rpy="0 0 0" xyz="0.0995 -0.0394 0.017"/>
    <parent link="front_bracket"/>
    <child link="front_right_hip"/>
    <limit effort="4.0" lower="-1.04" upper="1.04" velocity="4.0"/>
    <joint_properties damping="0.0" friction="0.0"/>
  </joint>
  <link name="front_right_upper_leg">
    <visual>
      <origin rpy="0 0 1.57079632679" xyz="-0.252 0.12 -0.055"/>
      <geometry>
        <mesh filename="package://mini_ros/stl/OpenQuadruped/RIGHT_UPPER_LEG.stl" scale="1 1 1"/>
      </geometry>
      <material name="maroon"/>
    </visual>
    <collision>
      <origin rpy="0 0 1.57079632679" xyz="0 -0.02 -0.05"/>
      <geometry>
        <box size="0.035 0.035 0.11"/>
      </geometry>
    </collision>
    <inertial>
      <mass value="0.13"/>
      <origin rpy="0 0 0" xyz="0 0 0"/>
      <!-- Inertial Axes -->
      <inertia ixx="0.000144354166667" ixy="0" ixz="0" iyx="0" iyy="0.000144354166667" iyz="0" izx="0" izy="0" izz="2.65416666667e-05"/>
    </inertial>
  </link>
  <joint name="motor_front_right_upper_leg" type="revolute">
    <axis xyz="0 1 0"/>
    <origin rpy="0 0 0" xyz="0.0015 -0.045 -0.0087"/>
    <parent link="front_right_hip"/>
    <child link="front_right_upper_leg"/>
    <limit effort="1000.0" lower="-1.57079632679" upper="2.59" velocity="0.7"/>
    <joint_properties damping="0.0" friction="0.0"/>
  </joint>

  
  <link name="front_right_lower_leg">
    <visual>
      <origin rpy="0 0 1.57079632679" xyz="-0.247 0.138 0.0535"/>
      <geometry>
        <mesh filename="package://mini_ros/stl/OpenQuadruped/RIGHT_LOWER_LEG.stl" scale="1 1 1"/>
      </geometry>
      <material name="yellow"/>
    </visual>
    <collision>
      <origin rpy="0 0 1.57079632679" xyz="0 0 -0.04"/>
      <geometry>
        <box size="0.035 0.035 0.10"/>
      </geometry>
    </collision>
    <inertial>
      <mass value="0.05"/>
      <origin rpy="0 0 0" xyz="0 0 0"/>
      <!-- Inertial Axes -->
      <inertia ixx="6.51041666667e-05" ixy="0" ixz="0" iyx="0" iyy="6.51041666667e-05" iyz="0" izx="0" izy="0" izz="1.02083333333e-05"/>
    </inertial>
  </link>
  <joint name="motor_front_right_lower_leg" type="revolute">
    <axis xyz="0 1 0"/>
    <origin rpy="0 0 0" xyz="-0.005 -0.018 -0.109"/>
    <parent link="front_right_upper_leg"/>
    <child link="front_right_lower_leg"/>
    <limit effort="1000.0" lower="-2.9" upper="1.57079632679" velocity="0.7"/>
    <joint_properties damping="0.0" friction="0.0"/>
  </joint>

  
  <link name="front_right_foot">
    <visual>
      <origin rpy="0 0 1.57079632679" xyz="-0.247 0.138 0.18"/>
      <geometry>
        <mesh filename="package://mini_ros/stl/OpenQuadruped/RIGHT_FOOT.stl" scale="1 1 1"/>
      </geometry>
      <material name="orange"/>
    </visual>
    <collision>
      <origin rpy="0 0 1.57079632679" xyz="-0.247 0.138 0.18"/>
      <geometry>
        <mesh filename="package://mini_ros/stl/OpenQuadruped/RIGHT_FOOT.stl" scale="1 1 1"/>
      </geometry>
      <contact_coefficients mu="10.1"/>
    </collision>
    <inertial>
      <mass value="0.005"/>
      <origin rpy="0 0 0" xyz="0 0 0"/>
      <!-- Inertial Axes -->
      <inertia ixx="3.52083333333e-06" ixy="0" ixz="0" iyx="0" iyy="2.80208333333e-06" iyz="0" izx="0" izy="0" izz="2.80208333333e-06"/>
    </inertial>
  </link>
  <link name="front_right_foot_IMU">
    <visual>
      <origin rpy="0 0 1.57079632679" xyz="-0.247 0.138 0.18"/>
      <geometry>
        <mesh filename="package://mini_ros/stl/OpenQuadruped/RIGHT_FOOT_IMU.stl" scale="1 1 1"/>
      </geometry>
      <material name="blue"/>
    </visual>
    <inertial>
      <mass value="0.005"/>
      <origin rpy="0 0 0" xyz="0 0 0"/>
      <!-- Inertial Axes -->
      <inertia ixx="3.52083333333e-06" ixy="0" ixz="0" iyx="0" iyy="2.80208333333e-06" iyz="0" izx="0" izy="0" izz="2.80208333333e-06"/>
    </inertial>
  </link>
  <link name="front_right_lower_CFP">
    <visual>
      <origin rpy="0 0 1.57079632679" xyz="-0.247 0.138 0.18"/>
      <geometry>
        <mesh filename="package://mini_ros/stl/OpenQuadruped/RIGHT_LOWER_CFP.stl" scale="1 1 1"/>
      </geometry>
      <material name="CFP"/>
    </visual>
    <inertial>
      <mass value="0.005"/>
      <origin rpy="0 0 0" xyz="0 0 0"/>
      <!-- Inertial Axes -->
      <inertia ixx="3.52083333333e-06" ixy="0" ixz="0" iyx="0" iyy="2.80208333333e-06" iyz="0" izx="0" izy="0" izz="2.80208333333e-06"/>
    </inertial>
  </link>
  
  <link name="front_right_foot_servo">
    <visual>
      <origin rpy="0 0 1.57079632679" xyz="-0.247 0.138 0.18"/>
      <geometry>
        <mesh filename="package://mini_ros/stl/OpenQuadruped/RIGHT_LOWER_SERVO.stl" scale="1 1 1"/>
      </geometry>
      <material name="black"/>
    </visual>
    <inertial>
      <mass value="0.005"/>
      <origin rpy="0 0 0" xyz="0 0 0"/>
      <!-- Inertial Axes -->
      <inertia ixx="3.52083333333e-06" ixy="0" ixz="0" iyx="0" iyy="2.80208333333e-06" iyz="0" izx="0" izy="0" izz="2.80208333333e-06"/>
    </inertial>
  </link>
  
  <link name="front_right_upper_servo">
    <visual>
      <origin rpy="0 0 1.57079632679" xyz="-0.247 0.138 0.18"/>
      <geometry>
        <mesh filename="package://mini_ros/stl/OpenQuadruped/RIGHT_UPPER_SERVO.stl" scale="1 1 1"/>
      </geometry>
      <material name="black"/>
    </visual>
    <inertial>
      <mass value="0.005"/>
      <origin rpy="0 0 0" xyz="0 0 0"/>
      
      <inertia ixx="3.52083333333e-06" ixy="0" ixz="0" iyx="0" iyy="2.80208333333e-06" iyz="0" izx="0" izy="0" izz="2.80208333333e-06"/>
    </inertial>
  </link>
  <link name="front_right_upper_CFP">
    <visual>
      <origin rpy="0 0 1.57079632679" xyz="-0.247 0.138 0.18"/>
      <geometry>
        <mesh filename="package://mini_ros/stl/OpenQuadruped/RIGHT_UPPER_CFP.stl" scale="1 1 1"/>
      </geometry>
      <material name="black"/>
    </visual>
    <inertial>
      <mass value="0.005"/>
      <origin rpy="0 0 0" xyz="0 0 0"/>
      
      <inertia ixx="3.52083333333e-06" ixy="0" ixz="0" iyx="0" iyy="2.80208333333e-06" iyz="0" izx="0" izy="0" izz="2.80208333333e-06"/>
    </inertial>
  </link>


  
  
  <link name="back_right_hip">
    <visual>
      <origin rpy="0 0 1.57079632679" xyz="-0.25 0.074 -0.067"/>
      <geometry>
        <mesh filename="package://mini_ros/stl/OpenQuadruped/RIGHT_HIP.stl" scale="1 1 1"/>
      </geometry>
      <material name="white"/>
    </visual>
    <collision>
      <origin rpy="0 0 1.57079632679" xyz="0.015 -0.01 -0.01"/>
      <geometry>
        <box size="0.05 0.065 0.065"/>
      </geometry>
    </collision>
    <inertial>
      <mass value="0.2"/>
      <origin rpy="0 0 0" xyz="0 0 0"/>
      <!-- Inertial Axes -->
      <inertia ixx="0.000140833333333" ixy="0" ixz="0" iyx="0" iyy="0.000112083333333" iyz="0" izx="0" izy="0" izz="0.000112083333333"/>
    </inertial>
  </link>
  <joint name="motor_back_right_hip" type="revolute">
    <axis xyz="1 0 0"/>
    <origin rpy="0 0 0" xyz="-0.1365 -0.0394 0.022"/>
    <parent link="back_bracket"/>
    <child link="back_right_hip"/>
    <limit effort="1000.0" lower="-1.04" upper="1.04" velocity="0.7"/>
    <joint_properties damping="0.0" friction="0.0"/>
  </joint>
  <link name="back_right_upper_leg">
    <visual>
      <origin rpy="0 0 1.57079632679" xyz="-0.252 0.12 -0.055"/>
      <geometry>
        <mesh filename="package://mini_ros/stl/OpenQuadruped/RIGHT_UPPER_LEG.stl" scale="1 1 1"/>
      </geometry>
      <material name="maroon"/>
    </visual>
    <collision>
      <origin rpy="0 0 1.57079632679" xyz="0 -0.02 -0.05"/>
      <geometry>
        <box size="0.035 0.035 0.11"/>
      </geometry>
    </collision>
    <inertial>
      <mass value="0.13"/>
      <origin rpy="0 0 0" xyz="0 0 0"/>
      <!-- Inertial Axes -->
      <inertia ixx="0.000144354166667" ixy="0" ixz="0" iyx="0" iyy="0.000144354166667" iyz="0" izx="0" izy="0" izz="2.65416666667e-05"/>
    </inertial>
  </link>
  <joint name="motor_back_right_upper_leg" type="revolute">
    <axis xyz="0 1 0"/>
    <origin rpy="0 0 0" xyz="0.0015 -0.045 -0.0087"/>
    <parent link="back_right_hip"/>
    <child link="back_right_upper_leg"/>
    <limit effort="1000.0" lower="-1.57079632679" upper="2.59" velocity="0.7"/>
    <joint_properties damping="0.0" friction="0.0"/>
  </joint>
  <link name="back_right_lower_leg">
    <visual>
      <origin rpy="0 0 1.57079632679" xyz="-0.247 0.138 0.0535"/>
      <geometry>
        <mesh filename="package://mini_ros/stl/OpenQuadruped/RIGHT_LOWER_LEG.stl" scale="1 1 1"/>
      </geometry>
      <material name="yellow"/>
    </visual>
    <collision>
      <origin rpy="0 0 1.57079632679" xyz="0 0 -0.04"/>
      <geometry>
        <box size="0.035 0.035 0.10"/>
      </geometry>
    </collision>
    <inertial>
      <mass value="0.05"/>
      <origin rpy="0 0 0" xyz="0 0 0"/>
      <!-- Inertial Axes -->
      <inertia ixx="6.51041666667e-05" ixy="0" ixz="0" iyx="0" iyy="6.51041666667e-05" iyz="0" izx="0" izy="0" izz="1.02083333333e-05"/>
    </inertial>
  </link>
  <joint name="motor_back_right_lower_leg" type="revolute">
    <axis xyz="0 1 0"/>
    <origin rpy="0 0 0" xyz="-0.005 -0.018 -0.109"/>
    <parent link="back_right_upper_leg"/>
    <child link="back_right_lower_leg"/>
    <limit effort="1000.0" lower="-2.9" upper="1.57079632679" velocity="0.7"/>
    <joint_properties damping="0.0" friction="0.0"/>
  </joint>
  <link name="back_right_foot">
    <visual>
      <origin rpy="0 0 1.57079632679" xyz="-0.247 0.138 0.18"/>
      <geometry>
        <mesh filename="package://mini_ros/stl/OpenQuadruped/RIGHT_FOOT.stl" scale="1 1 1"/>
      </geometry>
      <material name="orange"/>
    </visual>
    <collision>
      <origin rpy="0 0 1.57079632679" xyz="-0.247 0.138 0.18"/>
      <geometry>
        <mesh filename="package://mini_ros/stl/OpenQuadruped/RIGHT_FOOT.stl" scale="1 1 1"/>
      </geometry>
      <contact_coefficients mu="10.1"/>
    </collision>
    <inertial>
      <mass value="0.005"/>
      <origin rpy="0 0 0" xyz="0 0 0"/>
      <!-- Inertial Axes -->
      <inertia ixx="3.52083333333e-06" ixy="0" ixz="0" iyx="0" iyy="2.80208333333e-06" iyz="0" izx="0" izy="0" izz="2.80208333333e-06"/>
    </inertial>
  </link>
  <link name="back_right_foot_IMU">
    <visual>
      <origin rpy="0 0 1.57079632679" xyz="-0.247 0.138 0.18"/>
      <geometry>
        <mesh filename="package://mini_ros/stl/OpenQuadruped/RIGHT_FOOT_IMU.stl" scale="1 1 1"/>
      </geometry>
      <material name="blue"/>
    </visual>
    <inertial>
      <mass value="0.005"/>
      <origin rpy="0 0 0" xyz="0 0 0"/>
      <!-- Inertial Axes -->
      <inertia ixx="3.52083333333e-06" ixy="0" ixz="0" iyx="0" iyy="2.80208333333e-06" iyz="0" izx="0" izy="0" izz="2.80208333333e-06"/>
    </inertial>
  </link>
  <link name="back_right_lower_CFP">
    <visual>
      <origin rpy="0 0 1.57079632679" xyz="-0.247 0.138 0.18"/>
      <geometry>
        <mesh filename="package://mini_ros/stl/OpenQuadruped/RIGHT_LOWER_CFP.stl" scale="1 1 1"/>
      </geometry>
      <material name="black"/>
    </visual>
    <inertial>
      <mass value="0.005"/>
      <origin rpy="0 0 0" xyz="0 0 0"/>
      <!-- Inertial Axes -->
      <inertia ixx="3.52083333333e-06" ixy="0" ixz="0" iyx="0" iyy="2.80208333333e-06" iyz="0" izx="0" izy="0" izz="2.80208333333e-06"/>
    </inertial>
  </link>
  <link name="back_right_foot_servo">
    <visual>
      <origin rpy="0 0 1.57079632679" xyz="-0.247 0.138 0.18"/>
      <geometry>
        <mesh filename="package://mini_ros/stl/OpenQuadruped/RIGHT_LOWER_SERVO.stl" scale="1 1 1"/>
      </geometry>
      <material name="black"/>
    </visual>
    <inertial>
      <mass value="0.005"/>
      <origin rpy="0 0 0" xyz="0 0 0"/>
      <!-- Inertial Axes -->
      <inertia ixx="3.52083333333e-06" ixy="0" ixz="0" iyx="0" iyy="2.80208333333e-06" iyz="0" izx="0" izy="0" izz="2.80208333333e-06"/>
    </inertial>
  </link>

  <joint name="front_right_leg_foot" type="fixed">
    <origin rpy="0 0 0" xyz="0 0 -0.1265"/>
    <parent link="front_right_lower_leg"/>
    <child link="front_right_foot"/>
  </joint>
  <joint name="front_right_leg_foot_IMU" type="fixed">
    <origin rpy="0 0 0" xyz="0 0 -0.1265"/>
    <parent link="front_right_lower_leg"/>
    <child link="front_right_foot_IMU"/>
  </joint>
  <joint name="front_right_leg_lower_CFP" type="fixed">
    <origin rpy="0 0 0" xyz="0 0 -0.1265"/>
    <parent link="front_right_lower_leg"/>
    <child link="front_right_lower_CFP"/>
  </joint>
  <joint name="front_right_leg_foot_servo" type="fixed">
    <origin rpy="0 0 0" xyz="0 0 -0.1265"/>
    <parent link="front_right_lower_leg"/>
    <child link="front_right_foot_servo"/>
  </joint>
  
  <joint name="front_right_leg_upper_servo" type="fixed">
    <origin rpy="0 0 0" xyz="-0.005 -0.01 -0.235"/>
    <parent link="front_right_upper_leg"/>
    <child link="front_right_upper_servo"/>
  </joint>
  <joint name="front_right_upper_CFP" type="fixed">
    <origin rpy="0 0 0" xyz="-0.005 -0.01 -0.235"/>
    <parent link="front_right_upper_leg"/>
    <child link="front_right_upper_CFP"/>
  </joint>
    
  <joint name="back_right_leg_foot" type="fixed">
    <origin rpy="0 0 0" xyz="0 0 -0.1265"/>
    <parent link="back_right_lower_leg"/>
    <child link="back_right_foot"/>
  </joint>
  <joint name="back_right_leg_foot_IMU" type="fixed">
    <origin rpy="0 0 0" xyz="0 0 -0.1265"/>
    <parent link="back_right_lower_leg"/>
    <child link="back_right_foot_IMU"/>
  </joint>
  <joint name="back_right_leg_lower_CFP" type="fixed">
    <origin rpy="0 0 0" xyz="0 0 -0.1265"/>
    <parent link="back_right_lower_leg"/>
    <child link="back_right_lower_CFP"/>
  </joint>
  <joint name="back_right_leg_foot_servo" type="fixed">
    <origin rpy="0 0 0" xyz="0 0 -0.1265"/>
    <parent link="back_right_lower_leg"/>
    <child link="back_right_foot_servo"/>
  </joint>
  <joint name="base_battery" type="fixed">
    <origin rpy="0 0 0" xyz="-0.01 0 -0.0225"/>
    <parent link="base_link"/>
    <child link="battery"/>
  </joint>
  <joint name="base_cfr_core" type="fixed">
    <origin rpy="0 0 0" xyz="-0.01 0 -0.0225"/>
    <parent link="base_link"/>
    <child link="cfr_core"/>
  </joint>
  <joint name="base_m5paper" type="fixed">
    <origin rpy="0 0 0" xyz="-0.01 0 -0.0225"/>
    <parent link="base_link"/>
    <child link="m5paper"/>
  </joint>
  <joint name="base_rpi_lidar" type="fixed">
    <origin rpy="0 0 0" xyz="-0.01 0 -0.0225"/>
    <parent link="base_link"/>
    <child link="rpi_lidar"/>
  </joint>
  <joint name="base_rpi_5" type="fixed">
    <origin rpy="0 0 0" xyz="-0.01 0 -0.0225"/>
    <parent link="base_link"/>
    <child link="rpi_5"/>
  </joint>
  <joint name="base_oakd_lite" type="fixed">
    <origin rpy="0 0 0" xyz="-0.01 0 -0.0225"/>
    <parent link="base_link"/>
    <child link="oak_d_lite"/>
  </joint>
    <joint name="base_insta360" type="fixed">
    <origin rpy="0 0 0" xyz="-0.01 0 -0.0225"/>
    <parent link="base_link"/>
    <child link="insta_360"/>
  </joint>
  <joint name="base_front" type="fixed">
    <origin rpy="0 0 0" xyz="0 0 0"/>
    <parent link="base_link"/>
    <child link="front"/>
  </joint>
  <joint name="base_back" type="fixed">
    <origin rpy="0 0 0" xyz="0 0 0"/>
    <parent link="base_link"/>
    <child link="back"/>
  </joint>
  <joint name="base_front_bracket" type="fixed">
    <origin rpy="0 0 0" xyz="0 0 0"/>
    <parent link="base_link"/>
    <child link="front_bracket"/>
  </joint>
  <joint name="base_back_bracket" type="fixed">
    <origin rpy="0 0 0" xyz="0 0 0"/>
    <parent link="base_link"/>
    <child link="back_bracket"/>
  </joint>
</robot>
